2019-12-05 14:20:21,206 ERROR: Exception on /user/steve [GET] [in /Users/scammons/Projects/learn_flask/venv/lib/python3.7/site-packages/flask/app.py:1891]
Traceback (most recent call last):
  File "/Users/scammons/Projects/learn_flask/venv/lib/python3.7/site-packages/flask/app.py", line 2446, in wsgi_app
    response = self.full_dispatch_request()
  File "/Users/scammons/Projects/learn_flask/venv/lib/python3.7/site-packages/flask/app.py", line 1951, in full_dispatch_request
    rv = self.handle_user_exception(e)
  File "/Users/scammons/Projects/learn_flask/venv/lib/python3.7/site-packages/flask/app.py", line 1820, in handle_user_exception
    reraise(exc_type, exc_value, tb)
  File "/Users/scammons/Projects/learn_flask/venv/lib/python3.7/site-packages/flask/_compat.py", line 39, in reraise
    raise value
  File "/Users/scammons/Projects/learn_flask/venv/lib/python3.7/site-packages/flask/app.py", line 1949, in full_dispatch_request
    rv = self.dispatch_request()
  File "/Users/scammons/Projects/learn_flask/venv/lib/python3.7/site-packages/flask/app.py", line 1935, in dispatch_request
    return self.view_functions[rule.endpoint](**req.view_args)
  File "/Users/scammons/Projects/learn_flask/venv/lib/python3.7/site-packages/flask_login/utils.py", line 261, in decorated_view
    return func(*args, **kwargs)
  File "/Users/scammons/Projects/learn_flask/app/routes.py", line 121, in user
    posts = Post.query.filter_by(author=user.id).all()
  File "/Users/scammons/Projects/learn_flask/venv/lib/python3.7/site-packages/sqlalchemy/orm/query.py", line 1825, in filter_by
    for key, value in kwargs.items()
  File "/Users/scammons/Projects/learn_flask/venv/lib/python3.7/site-packages/sqlalchemy/orm/query.py", line 1825, in <listcomp>
    for key, value in kwargs.items()
  File "/Users/scammons/Projects/learn_flask/venv/lib/python3.7/site-packages/sqlalchemy/sql/operators.py", line 365, in __eq__
    return self.operate(eq, other)
  File "/Users/scammons/Projects/learn_flask/venv/lib/python3.7/site-packages/sqlalchemy/orm/attributes.py", line 217, in operate
    return op(self.comparator, *other, **kwargs)
  File "/Users/scammons/Projects/learn_flask/venv/lib/python3.7/site-packages/sqlalchemy/orm/relationships.py", line 1111, in __eq__
    other, adapt_source=self.adapter
  File "/Users/scammons/Projects/learn_flask/venv/lib/python3.7/site-packages/sqlalchemy/orm/relationships.py", line 1484, in _optimized_compare
    state = attributes.instance_state(state)
AttributeError: 'int' object has no attribute '_sa_instance_state'
2019-12-05 14:20:40,979 INFO: Microblog startup [in /Users/scammons/Projects/learn_flask/app/__init__.py:48]
2019-12-05 14:20:41,823 ERROR: Exception on /user/steve [GET] [in /Users/scammons/Projects/learn_flask/venv/lib/python3.7/site-packages/flask/app.py:1891]
Traceback (most recent call last):
  File "/Users/scammons/Projects/learn_flask/venv/lib/python3.7/site-packages/flask/app.py", line 2446, in wsgi_app
    response = self.full_dispatch_request()
  File "/Users/scammons/Projects/learn_flask/venv/lib/python3.7/site-packages/flask/app.py", line 1951, in full_dispatch_request
    rv = self.handle_user_exception(e)
  File "/Users/scammons/Projects/learn_flask/venv/lib/python3.7/site-packages/flask/app.py", line 1820, in handle_user_exception
    reraise(exc_type, exc_value, tb)
  File "/Users/scammons/Projects/learn_flask/venv/lib/python3.7/site-packages/flask/_compat.py", line 39, in reraise
    raise value
  File "/Users/scammons/Projects/learn_flask/venv/lib/python3.7/site-packages/flask/app.py", line 1949, in full_dispatch_request
    rv = self.dispatch_request()
  File "/Users/scammons/Projects/learn_flask/venv/lib/python3.7/site-packages/flask/app.py", line 1935, in dispatch_request
    return self.view_functions[rule.endpoint](**req.view_args)
  File "/Users/scammons/Projects/learn_flask/venv/lib/python3.7/site-packages/flask_login/utils.py", line 261, in decorated_view
    return func(*args, **kwargs)
  File "/Users/scammons/Projects/learn_flask/app/routes.py", line 122, in user
    posts = Post.query.filter_by(author=user.id).all()
  File "/Users/scammons/Projects/learn_flask/venv/lib/python3.7/site-packages/sqlalchemy/orm/query.py", line 1825, in filter_by
    for key, value in kwargs.items()
  File "/Users/scammons/Projects/learn_flask/venv/lib/python3.7/site-packages/sqlalchemy/orm/query.py", line 1825, in <listcomp>
    for key, value in kwargs.items()
  File "/Users/scammons/Projects/learn_flask/venv/lib/python3.7/site-packages/sqlalchemy/sql/operators.py", line 365, in __eq__
    return self.operate(eq, other)
  File "/Users/scammons/Projects/learn_flask/venv/lib/python3.7/site-packages/sqlalchemy/orm/attributes.py", line 217, in operate
    return op(self.comparator, *other, **kwargs)
  File "/Users/scammons/Projects/learn_flask/venv/lib/python3.7/site-packages/sqlalchemy/orm/relationships.py", line 1111, in __eq__
    other, adapt_source=self.adapter
  File "/Users/scammons/Projects/learn_flask/venv/lib/python3.7/site-packages/sqlalchemy/orm/relationships.py", line 1484, in _optimized_compare
    state = attributes.instance_state(state)
AttributeError: 'int' object has no attribute '_sa_instance_state'
2019-12-05 14:20:55,170 INFO: Microblog startup [in /Users/scammons/Projects/learn_flask/app/__init__.py:48]
2019-12-05 15:15:04,497 INFO: Microblog startup [in /Users/scammons/Projects/learn_flask/app/__init__.py:48]
2019-12-05 15:15:38,837 ERROR: Exception on /explore [GET] [in /Users/scammons/Projects/learn_flask/venv/lib/python3.7/site-packages/flask/app.py:1891]
Traceback (most recent call last):
  File "/Users/scammons/Projects/learn_flask/venv/lib/python3.7/site-packages/flask/app.py", line 2446, in wsgi_app
    response = self.full_dispatch_request()
  File "/Users/scammons/Projects/learn_flask/venv/lib/python3.7/site-packages/flask/app.py", line 1951, in full_dispatch_request
    rv = self.handle_user_exception(e)
  File "/Users/scammons/Projects/learn_flask/venv/lib/python3.7/site-packages/flask/app.py", line 1820, in handle_user_exception
    reraise(exc_type, exc_value, tb)
  File "/Users/scammons/Projects/learn_flask/venv/lib/python3.7/site-packages/flask/_compat.py", line 39, in reraise
    raise value
  File "/Users/scammons/Projects/learn_flask/venv/lib/python3.7/site-packages/flask/app.py", line 1949, in full_dispatch_request
    rv = self.dispatch_request()
  File "/Users/scammons/Projects/learn_flask/venv/lib/python3.7/site-packages/flask/app.py", line 1935, in dispatch_request
    return self.view_functions[rule.endpoint](**req.view_args)
  File "/Users/scammons/Projects/learn_flask/venv/lib/python3.7/site-packages/flask_login/utils.py", line 261, in decorated_view
    return func(*args, **kwargs)
  File "/Users/scammons/Projects/learn_flask/app/routes.py", line 35, in explore
    page, app.config['POSTS_PER_PAGE'], False)
NameError: name 'page' is not defined
2019-12-05 15:15:43,990 ERROR: Exception on /explore [GET] [in /Users/scammons/Projects/learn_flask/venv/lib/python3.7/site-packages/flask/app.py:1891]
Traceback (most recent call last):
  File "/Users/scammons/Projects/learn_flask/venv/lib/python3.7/site-packages/flask/app.py", line 2446, in wsgi_app
    response = self.full_dispatch_request()
  File "/Users/scammons/Projects/learn_flask/venv/lib/python3.7/site-packages/flask/app.py", line 1951, in full_dispatch_request
    rv = self.handle_user_exception(e)
  File "/Users/scammons/Projects/learn_flask/venv/lib/python3.7/site-packages/flask/app.py", line 1820, in handle_user_exception
    reraise(exc_type, exc_value, tb)
  File "/Users/scammons/Projects/learn_flask/venv/lib/python3.7/site-packages/flask/_compat.py", line 39, in reraise
    raise value
  File "/Users/scammons/Projects/learn_flask/venv/lib/python3.7/site-packages/flask/app.py", line 1949, in full_dispatch_request
    rv = self.dispatch_request()
  File "/Users/scammons/Projects/learn_flask/venv/lib/python3.7/site-packages/flask/app.py", line 1935, in dispatch_request
    return self.view_functions[rule.endpoint](**req.view_args)
  File "/Users/scammons/Projects/learn_flask/venv/lib/python3.7/site-packages/flask_login/utils.py", line 261, in decorated_view
    return func(*args, **kwargs)
  File "/Users/scammons/Projects/learn_flask/app/routes.py", line 35, in explore
    page, app.config['POSTS_PER_PAGE'], False)
NameError: name 'page' is not defined
2019-12-05 15:15:45,282 ERROR: Exception on /explore [GET] [in /Users/scammons/Projects/learn_flask/venv/lib/python3.7/site-packages/flask/app.py:1891]
Traceback (most recent call last):
  File "/Users/scammons/Projects/learn_flask/venv/lib/python3.7/site-packages/flask/app.py", line 2446, in wsgi_app
    response = self.full_dispatch_request()
  File "/Users/scammons/Projects/learn_flask/venv/lib/python3.7/site-packages/flask/app.py", line 1951, in full_dispatch_request
    rv = self.handle_user_exception(e)
  File "/Users/scammons/Projects/learn_flask/venv/lib/python3.7/site-packages/flask/app.py", line 1820, in handle_user_exception
    reraise(exc_type, exc_value, tb)
  File "/Users/scammons/Projects/learn_flask/venv/lib/python3.7/site-packages/flask/_compat.py", line 39, in reraise
    raise value
  File "/Users/scammons/Projects/learn_flask/venv/lib/python3.7/site-packages/flask/app.py", line 1949, in full_dispatch_request
    rv = self.dispatch_request()
  File "/Users/scammons/Projects/learn_flask/venv/lib/python3.7/site-packages/flask/app.py", line 1935, in dispatch_request
    return self.view_functions[rule.endpoint](**req.view_args)
  File "/Users/scammons/Projects/learn_flask/venv/lib/python3.7/site-packages/flask_login/utils.py", line 261, in decorated_view
    return func(*args, **kwargs)
  File "/Users/scammons/Projects/learn_flask/app/routes.py", line 35, in explore
    page, app.config['POSTS_PER_PAGE'], False)
NameError: name 'page' is not defined
